<robot name="uf850">
    <link name="base_link">
        <visual>
            <origin xyz="0.0 0.0 0.0" rpy="0.0 0.0 0.0"/>
            <geometry>
                <mesh filename="package://uf850_description/meshes/link_base.stl" scale="1 1 1"/>
            </geometry>
            <material name="base_color">
                <color rgba="0. 0.6 0.6 1"/>
            </material>
        </visual>
    </link>

    <link name="link1">
        <visual>
            
            <geometry>
                <mesh filename="package://uf850_description/meshes/link1.stl" scale="1 1 1"/>
            </geometry>
            <!-- <material name="base_color">
                <color rgba="0. 0.6 0.6 1"/>
            </material> -->
        </visual>
    </link>

    <joint name="base_link_to_link1" type="revolute">
        <origin xyz="0.0 0.0 0.35" rpy="0.0 0.0 0.0"/>
        <parent link="base_link"/>
        <child link="link1"/>
        <axis xyz="0 0.0 1"/>
        <limit lower="-3.14" upper="3.14" effort="0.0" velocity="0.0"/>
    </joint>

    <link name="link2">
        <visual>
            <geometry>
                <mesh filename="package://uf850_description/meshes/link2.stl" scale="1 1 1"/>
            </geometry>
            <!-- <material name="base_color">
                <color rgba="0. 0.6 0.6 1"/>
            </material> -->
        </visual>
    </link>

    <joint name="link1_to_link2" type="revolute">
        <origin xyz="0.0 0.0 0.0" rpy="1.57 -1.57 0.0"/>
        <parent link="link1"/>
        <child link="link2"/>
        <axis xyz="0 0.0 1"/>
        <limit lower="-3.14" upper="3.14" effort="0.0" velocity="0.0"/>
    </joint>

      <link name="link3">
        <visual>
            <geometry>
                <mesh filename="package://uf850_description/meshes/link3.stl" scale="1 1 1"/>
            </geometry>
            <!-- <material name="base_color">
                <color rgba="0. 0.6 0.6 1"/>
            </material> -->
        </visual>
    </link>

    <joint name="link2_to_link3" type="revolute">
        <origin xyz="0.39 0.0 0.0" rpy="0.0 3.14 1.57"/>
        <parent link="link2"/>
        <child link="link3"/>
        <axis xyz="0 0.0 1"/>
        <limit lower="-3.14" upper="3.14" effort="0.0" velocity="0.0"/>
    </joint>

    <link name="link4">
        <visual>
            <geometry>
                <mesh filename="package://uf850_description/meshes/link4.stl" scale="1 1 1"/>
            </geometry>
            <!-- <material name="base_color">
                <color rgba="0. 0.6 0.6 1"/>
            </material> -->
        </visual>
    </link>

    <joint name="link3_to_link4" type="revolute">
        <origin xyz="0.15 0.41 0.0" rpy="-1.57 0 0"/>
        <parent link="link3"/>
        <child link="link4"/>
        <axis xyz="0 0.0 1"/>
        <limit lower="-3.14" upper="3.14" effort="0.0" velocity="0.0"/>
    </joint>

    <link name="link5">
        <visual>
            <geometry>
                <mesh filename="package://uf850_description/meshes/link5.stl" scale="1 1 1"/>
            </geometry>
            <!-- <material name="base_color">
                <color rgba="0. 0.6 0.6 1"/>
            </material> -->
        </visual>
    </link>

    <joint name="link4_to_link5" type="revolute">
        <origin xyz="0 -0.01 0.0" rpy="-1.57 0 0"/>
        <parent link="link4"/>
        <child link="link5"/>
        <axis xyz="0 0.0 1"/>
        <limit lower="-3.14" upper="3.14" effort="0.0" velocity="0.0"/>
    </joint>

    <link name="link6">
        <visual>
            <geometry>
                <mesh filename="package://uf850_description/meshes/link6.stl" scale="1 1 1"/>
            </geometry>
            <!-- <material name="base_color">
                <color rgba="0. 0.6 0.6 1"/>
            </material> -->
        </visual>
    </link>

    <joint name="link5_to_link6" type="revolute">
        <origin xyz="0 -0.09 0.0" rpy="1.57 0 0"/>
        <parent link="link5"/>
        <child link="link6"/>
        <axis xyz="0 0.0 1"/>
        <limit lower="-3.14" upper="3.14" effort="0.0" velocity="0.0"/>
    </joint>

</robot>